imallikarjun@ubuntu-01:~/scripts/nsxalb/dev$ python3 alb-vsInventory-v0.2_WIP.py
/usr/lib/python3/dist-packages/requests/__init__.py:87: RequestsDependencyWarning: urllib3 (2.2.2) or chardet (4.0.0) doesn't match a supported version!
  warnings.warn("urllib3 ({}) or chardet ({}) doesn't match a supported "
--- Logging error ---
Traceback (most recent call last):
  File "/home/imallikarjun/scripts/nsxalb/dev/alb-vsInventory-v0.2_WIP.py", line 607, in parse_controllers
    u, p = val.split(",", 1)
ValueError: not enough values to unpack (expected 2, got 1)

During handling of the above exception, another exception occurred:

Traceback (most recent call last):
  File "/usr/lib/python3.10/logging/__init__.py", line 1100, in emit
    msg = self.format(record)
  File "/usr/lib/python3.10/logging/__init__.py", line 943, in format
    return fmt.format(record)
  File "/usr/lib/python3.10/logging/__init__.py", line 681, in format
    s = self.formatMessage(record)
  File "/usr/lib/python3.10/logging/__init__.py", line 650, in formatMessage
    return self._style.format(record)
  File "/usr/lib/python3.10/logging/__init__.py", line 440, in format
    return self._format(record)
  File "/usr/lib/python3.10/logging/__init__.py", line 436, in _format
    return self._fmt % values
ValueError: unsupported format character 'Y' (0x59) at index 1
Call stack:
  File "/home/imallikarjun/scripts/nsxalb/dev/alb-vsInventory-v0.2_WIP.py", line 733, in <module>
    main()
  File "/home/imallikarjun/scripts/nsxalb/dev/alb-vsInventory-v0.2_WIP.py", line 653, in main
    controllers = parse_controllers(cfg)
  File "/home/imallikarjun/scripts/nsxalb/dev/alb-vsInventory-v0.2_WIP.py", line 610, in parse_controllers
    logging.warning("Invalid creds format for %s; using DEFAULT creds.", host)
Message: 'Invalid creds format for %s; using DEFAULT creds.'
Arguments: ('avi_user',)
--- Logging error ---
Traceback (most recent call last):
  File "/home/imallikarjun/scripts/nsxalb/dev/alb-vsInventory-v0.2_WIP.py", line 607, in parse_controllers
    u, p = val.split(",", 1)
ValueError: not enough values to unpack (expected 2, got 1)

During handling of the above exception, another exception occurred:

Traceback (most recent call last):
  File "/usr/lib/python3.10/logging/__init__.py", line 1100, in emit
    msg = self.format(record)
  File "/usr/lib/python3.10/logging/__init__.py", line 943, in format
    return fmt.format(record)
  File "/usr/lib/python3.10/logging/__init__.py", line 681, in format
    s = self.formatMessage(record)
  File "/usr/lib/python3.10/logging/__init__.py", line 650, in formatMessage
    return self._style.format(record)
  File "/usr/lib/python3.10/logging/__init__.py", line 440, in format
    return self._format(record)
  File "/usr/lib/python3.10/logging/__init__.py", line 436, in _format
    return self._fmt % values
ValueError: unsupported format character 'Y' (0x59) at index 1
Call stack:
  File "/home/imallikarjun/scripts/nsxalb/dev/alb-vsInventory-v0.2_WIP.py", line 733, in <module>
    main()
  File "/home/imallikarjun/scripts/nsxalb/dev/alb-vsInventory-v0.2_WIP.py", line 653, in main
    controllers = parse_controllers(cfg)
  File "/home/imallikarjun/scripts/nsxalb/dev/alb-vsInventory-v0.2_WIP.py", line 610, in parse_controllers
    logging.warning("Invalid creds format for %s; using DEFAULT creds.", host)
Message: 'Invalid creds format for %s; using DEFAULT creds.'
Arguments: ('avi_pass',)
--- Logging error ---
Traceback (most recent call last):
  File "/usr/lib/python3.10/logging/__init__.py", line 1100, in emit
    msg = self.format(record)
  File "/usr/lib/python3.10/logging/__init__.py", line 943, in format
    return fmt.format(record)
  File "/usr/lib/python3.10/logging/__init__.py", line 681, in format
    s = self.formatMessage(record)
  File "/usr/lib/python3.10/logging/__init__.py", line 650, in formatMessage
    return self._style.format(record)
  File "/usr/lib/python3.10/logging/__init__.py", line 440, in format
    return self._format(record)
  File "/usr/lib/python3.10/logging/__init__.py", line 436, in _format
    return self._fmt % values
ValueError: unsupported format character 'Y' (0x59) at index 1
Call stack:
  File "/home/imallikarjun/scripts/nsxalb/dev/alb-vsInventory-v0.2_WIP.py", line 733, in <module>
    main()
  File "/home/imallikarjun/scripts/nsxalb/dev/alb-vsInventory-v0.2_WIP.py", line 658, in main
    logging.info("Controllers: %s", ", ".join([c for c, _ in controllers]))
Message: 'Controllers: %s'
Arguments: ('m00aviblb.corp.ad.sbi, avi_user, avi_pass',)
--- Logging error ---
Traceback (most recent call last):
  File "/usr/lib/python3.10/logging/__init__.py", line 1100, in emit
    msg = self.format(record)
  File "/usr/lib/python3.10/logging/__init__.py", line 943, in format
    return fmt.format(record)
  File "/usr/lib/python3.10/logging/__init__.py", line 681, in format
    s = self.formatMessage(record)
  File "/usr/lib/python3.10/logging/__init__.py", line 650, in formatMessage
    return self._style.format(record)
  File "/usr/lib/python3.10/logging/__init__.py", line 440, in format
    return self._format(record)
  File "/usr/lib/python3.10/logging/__init__.py", line 436, in _format
    return self._fmt % values
ValueError: unsupported format character 'Y' (0x59) at index 1
Call stack:
  File "/home/imallikarjun/scripts/nsxalb/dev/alb-vsInventory-v0.2_WIP.py", line 733, in <module>
    main()
  File "/home/imallikarjun/scripts/nsxalb/dev/alb-vsInventory-v0.2_WIP.py", line 659, in main
    logging.info("Metrics: %s | step=%s | limit=%s", metrics_names, settings.get("api_step", 21600), settings.get("api_limit", 1))
Message: 'Metrics: %s | step=%s | limit=%s'
Arguments: (['l4_client.avg_bandwidth', 'l4_client.avg_new_established_conns', 'l4_client.avg_complete_conns', 'l4_client.max_open_conns', 'l7_client.avg_ssl_handshakes_new', 'l7_client.avg_ssl_connections', 'l7_client.avg_ssl_handshakes_reused'], '21600', '1')
--- Logging error ---
Traceback (most recent call last):
  File "/usr/local/lib/python3.10/dist-packages/urllib3/connection.py", line 196, in _new_conn
    sock = connection.create_connection(
  File "/usr/local/lib/python3.10/dist-packages/urllib3/util/connection.py", line 60, in create_connection
    for res in socket.getaddrinfo(host, port, family, socket.SOCK_STREAM):
  File "/usr/lib/python3.10/socket.py", line 955, in getaddrinfo
    for res in _socket.getaddrinfo(host, port, family, type, proto, flags):
socket.gaierror: [Errno -3] Temporary failure in name resolution

The above exception was the direct cause of the following exception:

Traceback (most recent call last):
  File "/usr/local/lib/python3.10/dist-packages/urllib3/connectionpool.py", line 789, in urlopen
    response = self._make_request(
  File "/usr/local/lib/python3.10/dist-packages/urllib3/connectionpool.py", line 490, in _make_request
    raise new_e
  File "/usr/local/lib/python3.10/dist-packages/urllib3/connectionpool.py", line 466, in _make_request
    self._validate_conn(conn)
  File "/usr/local/lib/python3.10/dist-packages/urllib3/connectionpool.py", line 1095, in _validate_conn
    conn.connect()
  File "/usr/local/lib/python3.10/dist-packages/urllib3/connection.py", line 615, in connect
    self.sock = sock = self._new_conn()
  File "/usr/local/lib/python3.10/dist-packages/urllib3/connection.py", line 203, in _new_conn
    raise NameResolutionError(self.host, self, e) from e
urllib3.exceptions.NameResolutionError: <urllib3.connection.HTTPSConnection object at 0x7f4949f4df30>: Failed to resolve 'avi_user' ([Errno -3] Temporary failure in name resolution)

The above exception was the direct cause of the following exception:

Traceback (most recent call last):
  File "/usr/lib/python3/dist-packages/requests/adapters.py", line 439, in send
    resp = conn.urlopen(
  File "/usr/local/lib/python3.10/dist-packages/urllib3/connectionpool.py", line 843, in urlopen
    retries = retries.increment(
  File "/usr/local/lib/python3.10/dist-packages/urllib3/util/retry.py", line 519, in increment
    raise MaxRetryError(_pool, url, reason) from reason  # type: ignore[arg-type]
urllib3.exceptions.MaxRetryError: HTTPSConnectionPool(host='avi_user', port=443): Max retries exceeded with url: /login (Caused by NameResolutionError("<urllib3.connection.HTTPSConnection object at 0x7f4949f4df30>: Failed to resolve 'avi_user' ([Errno -3] Temporary failure in name resolution)"))

During handling of the above exception, another exception occurred:

Traceback (most recent call last):
  File "/home/imallikarjun/scripts/nsxalb/dev/alb-vsInventory-v0.2_WIP.py", line 714, in main
    ctrl, vs_count, inv_secs, met_secs, total_secs = fut.result()
  File "/usr/lib/python3.10/concurrent/futures/_base.py", line 451, in result
    return self.__get_result()
  File "/usr/lib/python3.10/concurrent/futures/_base.py", line 403, in __get_result
    raise self._exception
  File "/usr/lib/python3.10/concurrent/futures/thread.py", line 58, in run
    result = self.fn(*self.args, **self.kwargs)
  File "/home/imallikarjun/scripts/nsxalb/dev/alb-vsInventory-v0.2_WIP.py", line 549, in controller_run
    client.login(creds[0], creds[1])
  File "/home/imallikarjun/scripts/nsxalb/dev/alb-vsInventory-v0.2_WIP.py", line 223, in login
    r = self.sess.post(url, json={"username": user, "password": password}, timeout=30)
  File "/usr/lib/python3/dist-packages/requests/sessions.py", line 592, in post
    return self.request('POST', url, data=data, json=json, **kwargs)
  File "/usr/lib/python3/dist-packages/requests/sessions.py", line 544, in request
    resp = self.send(prep, **send_kwargs)
  File "/usr/lib/python3/dist-packages/requests/sessions.py", line 657, in send
    r = adapter.send(request, **kwargs)
  File "/usr/lib/python3/dist-packages/requests/adapters.py", line 516, in send
    raise ConnectionError(e, request=request)
requests.exceptions.ConnectionError: HTTPSConnectionPool(host='avi_user', port=443): Max retries exceeded with url: /login (Caused by NameResolutionError("<urllib3.connection.HTTPSConnection object at 0x7f4949f4df30>: Failed to resolve 'avi_user' ([Errno -3] Temporary failure in name resolution)"))

During handling of the above exception, another exception occurred:

Traceback (most recent call last):
  File "/usr/lib/python3.10/logging/__init__.py", line 1100, in emit
    msg = self.format(record)
  File "/usr/lib/python3.10/logging/__init__.py", line 943, in format
    return fmt.format(record)
  File "/usr/lib/python3.10/logging/__init__.py", line 681, in format
    s = self.formatMessage(record)
  File "/usr/lib/python3.10/logging/__init__.py", line 650, in formatMessage
    return self._style.format(record)
  File "/usr/lib/python3.10/logging/__init__.py", line 440, in format
    return self._format(record)
  File "/usr/lib/python3.10/logging/__init__.py", line 436, in _format
    return self._fmt % values
ValueError: unsupported format character 'Y' (0x59) at index 1
Call stack:
  File "/home/imallikarjun/scripts/nsxalb/dev/alb-vsInventory-v0.2_WIP.py", line 733, in <module>
    main()
  File "/home/imallikarjun/scripts/nsxalb/dev/alb-vsInventory-v0.2_WIP.py", line 717, in main
    logging.error("Controller task error: %s", e)
Message: 'Controller task error: %s'
Arguments: (ConnectionError(MaxRetryError('HTTPSConnectionPool(host=\'avi_user\', port=443): Max retries exceeded with url: /login (Caused by NameResolutionError("<urllib3.connection.HTTPSConnection object at 0x7f4949f4df30>: Failed to resolve \'avi_user\' ([Errno -3] Temporary failure in name resolution)"))')),)
--- Logging error ---
Traceback (most recent call last):
  File "/usr/local/lib/python3.10/dist-packages/urllib3/connection.py", line 196, in _new_conn
    sock = connection.create_connection(
  File "/usr/local/lib/python3.10/dist-packages/urllib3/util/connection.py", line 60, in create_connection
    for res in socket.getaddrinfo(host, port, family, socket.SOCK_STREAM):
  File "/usr/lib/python3.10/socket.py", line 955, in getaddrinfo
    for res in _socket.getaddrinfo(host, port, family, type, proto, flags):
socket.gaierror: [Errno -3] Temporary failure in name resolution

The above exception was the direct cause of the following exception:

Traceback (most recent call last):
  File "/usr/local/lib/python3.10/dist-packages/urllib3/connectionpool.py", line 789, in urlopen
    response = self._make_request(
  File "/usr/local/lib/python3.10/dist-packages/urllib3/connectionpool.py", line 490, in _make_request
    raise new_e
  File "/usr/local/lib/python3.10/dist-packages/urllib3/connectionpool.py", line 466, in _make_request
    self._validate_conn(conn)
  File "/usr/local/lib/python3.10/dist-packages/urllib3/connectionpool.py", line 1095, in _validate_conn
    conn.connect()
  File "/usr/local/lib/python3.10/dist-packages/urllib3/connection.py", line 615, in connect
    self.sock = sock = self._new_conn()
  File "/usr/local/lib/python3.10/dist-packages/urllib3/connection.py", line 203, in _new_conn
    raise NameResolutionError(self.host, self, e) from e
urllib3.exceptions.NameResolutionError: <urllib3.connection.HTTPSConnection object at 0x7f4949f4e200>: Failed to resolve 'avi_pass' ([Errno -3] Temporary failure in name resolution)

The above exception was the direct cause of the following exception:

Traceback (most recent call last):
  File "/usr/lib/python3/dist-packages/requests/adapters.py", line 439, in send
    resp = conn.urlopen(
  File "/usr/local/lib/python3.10/dist-packages/urllib3/connectionpool.py", line 843, in urlopen
    retries = retries.increment(
  File "/usr/local/lib/python3.10/dist-packages/urllib3/util/retry.py", line 519, in increment
    raise MaxRetryError(_pool, url, reason) from reason  # type: ignore[arg-type]
urllib3.exceptions.MaxRetryError: HTTPSConnectionPool(host='avi_pass', port=443): Max retries exceeded with url: /login (Caused by NameResolutionError("<urllib3.connection.HTTPSConnection object at 0x7f4949f4e200>: Failed to resolve 'avi_pass' ([Errno -3] Temporary failure in name resolution)"))

During handling of the above exception, another exception occurred:

Traceback (most recent call last):
  File "/home/imallikarjun/scripts/nsxalb/dev/alb-vsInventory-v0.2_WIP.py", line 714, in main
    ctrl, vs_count, inv_secs, met_secs, total_secs = fut.result()
  File "/usr/lib/python3.10/concurrent/futures/_base.py", line 451, in result
    return self.__get_result()
  File "/usr/lib/python3.10/concurrent/futures/_base.py", line 403, in __get_result
    raise self._exception
  File "/usr/lib/python3.10/concurrent/futures/thread.py", line 58, in run
    result = self.fn(*self.args, **self.kwargs)
  File "/home/imallikarjun/scripts/nsxalb/dev/alb-vsInventory-v0.2_WIP.py", line 549, in controller_run
    client.login(creds[0], creds[1])
  File "/home/imallikarjun/scripts/nsxalb/dev/alb-vsInventory-v0.2_WIP.py", line 223, in login
    r = self.sess.post(url, json={"username": user, "password": password}, timeout=30)
  File "/usr/lib/python3/dist-packages/requests/sessions.py", line 592, in post
    return self.request('POST', url, data=data, json=json, **kwargs)
  File "/usr/lib/python3/dist-packages/requests/sessions.py", line 544, in request
    resp = self.send(prep, **send_kwargs)
  File "/usr/lib/python3/dist-packages/requests/sessions.py", line 657, in send
    r = adapter.send(request, **kwargs)
  File "/usr/lib/python3/dist-packages/requests/adapters.py", line 516, in send
    raise ConnectionError(e, request=request)
requests.exceptions.ConnectionError: HTTPSConnectionPool(host='avi_pass', port=443): Max retries exceeded with url: /login (Caused by NameResolutionError("<urllib3.connection.HTTPSConnection object at 0x7f4949f4e200>: Failed to resolve 'avi_pass' ([Errno -3] Temporary failure in name resolution)"))

During handling of the above exception, another exception occurred:

Traceback (most recent call last):
  File "/usr/lib/python3.10/logging/__init__.py", line 1100, in emit
    msg = self.format(record)
  File "/usr/lib/python3.10/logging/__init__.py", line 943, in format
    return fmt.format(record)
  File "/usr/lib/python3.10/logging/__init__.py", line 681, in format
    s = self.formatMessage(record)
  File "/usr/lib/python3.10/logging/__init__.py", line 650, in formatMessage
    return self._style.format(record)
  File "/usr/lib/python3.10/logging/__init__.py", line 440, in format
    return self._format(record)
  File "/usr/lib/python3.10/logging/__init__.py", line 436, in _format
    return self._fmt % values
ValueError: unsupported format character 'Y' (0x59) at index 1
Call stack:
  File "/home/imallikarjun/scripts/nsxalb/dev/alb-vsInventory-v0.2_WIP.py", line 733, in <module>
    main()
  File "/home/imallikarjun/scripts/nsxalb/dev/alb-vsInventory-v0.2_WIP.py", line 717, in main
    logging.error("Controller task error: %s", e)
Message: 'Controller task error: %s'
Arguments: (ConnectionError(MaxRetryError('HTTPSConnectionPool(host=\'avi_pass\', port=443): Max retries exceeded with url: /login (Caused by NameResolutionError("<urllib3.connection.HTTPSConnection object at 0x7f4949f4e200>: Failed to resolve \'avi_pass\' ([Errno -3] Temporary failure in name resolution)"))')),)
--- Logging error ---
Traceback (most recent call last):
  File "/usr/lib/python3.10/logging/__init__.py", line 1100, in emit
    msg = self.format(record)
  File "/usr/lib/python3.10/logging/__init__.py", line 943, in format
    return fmt.format(record)
  File "/usr/lib/python3.10/logging/__init__.py", line 681, in format
    s = self.formatMessage(record)
  File "/usr/lib/python3.10/logging/__init__.py", line 650, in formatMessage
    return self._style.format(record)
  File "/usr/lib/python3.10/logging/__init__.py", line 440, in format
    return self._format(record)
  File "/usr/lib/python3.10/logging/__init__.py", line 436, in _format
    return self._fmt % values
ValueError: unsupported format character 'Y' (0x59) at index 1
Call stack:
  File "/usr/lib/python3.10/threading.py", line 973, in _bootstrap
    self._bootstrap_inner()
  File "/usr/lib/python3.10/threading.py", line 1016, in _bootstrap_inner
    self.run()
  File "/usr/lib/python3.10/threading.py", line 953, in run
    self._target(*self._args, **self._kwargs)
  File "/usr/lib/python3.10/concurrent/futures/thread.py", line 83, in _worker
    work_item.run()
  File "/usr/lib/python3.10/concurrent/futures/thread.py", line 58, in run
    result = self.fn(*self.args, **self.kwargs)
  File "/home/imallikarjun/scripts/nsxalb/dev/alb-vsInventory-v0.2_WIP.py", line 549, in controller_run
    client.login(creds[0], creds[1])
  File "/home/imallikarjun/scripts/nsxalb/dev/alb-vsInventory-v0.2_WIP.py", line 225, in login
    logging.info("[%s] Logged in", self.base_hostname)
Message: '[%s] Logged in'
Arguments: ('m00aviblb.corp.ad.sbi',)
--- Logging error ---
Traceback (most recent call last):
  File "/usr/lib/python3.10/logging/__init__.py", line 1100, in emit
    msg = self.format(record)
  File "/usr/lib/python3.10/logging/__init__.py", line 943, in format
    return fmt.format(record)
  File "/usr/lib/python3.10/logging/__init__.py", line 681, in format
    s = self.formatMessage(record)
  File "/usr/lib/python3.10/logging/__init__.py", line 650, in formatMessage
    return self._style.format(record)
  File "/usr/lib/python3.10/logging/__init__.py", line 440, in format
    return self._format(record)
  File "/usr/lib/python3.10/logging/__init__.py", line 436, in _format
    return self._fmt % values
ValueError: unsupported format character 'Y' (0x59) at index 1
Call stack:
  File "/home/imallikarjun/scripts/nsxalb/dev/alb-vsInventory-v0.2_WIP.py", line 733, in <module>
    main()
  File "/home/imallikarjun/scripts/nsxalb/dev/alb-vsInventory-v0.2_WIP.py", line 727, in main
    logging.info("[%s] VS fetched: %s | inventory: %.2fs | metrics: %.2fs | total: %.2fs",
Message: '[%s] VS fetched: %s | inventory: %.2fs | metrics: %.2fs | total: %.2fs'
Arguments: ('m00aviblb.corp.ad.sbi', 25, 0.42955517768859863, 13.38269853591919, 14.119152784347534)
--- Logging error ---
Traceback (most recent call last):
  File "/usr/lib/python3.10/logging/__init__.py", line 1100, in emit
    msg = self.format(record)
  File "/usr/lib/python3.10/logging/__init__.py", line 943, in format
    return fmt.format(record)
  File "/usr/lib/python3.10/logging/__init__.py", line 681, in format
    s = self.formatMessage(record)
  File "/usr/lib/python3.10/logging/__init__.py", line 650, in formatMessage
    return self._style.format(record)
  File "/usr/lib/python3.10/logging/__init__.py", line 440, in format
    return self._format(record)
  File "/usr/lib/python3.10/logging/__init__.py", line 436, in _format
    return self._fmt % values
ValueError: unsupported format character 'Y' (0x59) at index 1
Call stack:
  File "/home/imallikarjun/scripts/nsxalb/dev/alb-vsInventory-v0.2_WIP.py", line 733, in <module>
    main()
  File "/home/imallikarjun/scripts/nsxalb/dev/alb-vsInventory-v0.2_WIP.py", line 729, in main
    logging.info("CSV written: %s (rows=%d)", out_csv, len(all_rows))
Message: 'CSV written: %s (rows=%d)'
Arguments: ('./alb_vsInventory_20251020T155551.csv', 25)
imallikarjun@ubuntu-01:~/scripts/nsxalb/dev$
